Workbook

Sheet Instrucciones
A1: Encuesta pre y post del taller práctico: pruebas de hipótesis con datos metagenómicos
A3: Para qué sirve | B3: Medir cuánto sabían los estudiantes sobre el tema antes del taller (PRE) y cuánto saben después (POST), qué tan capaces se sienten y cómo valoran el taller. La parte de conocimiento es idéntica en las dos aplicaciones, para poder comparar.
A4: Cuándo se aplica | B4: PRE: justo antes de empezar el taller. POST: al terminar, o en la sesión siguiente. Cada una toma unos 10 minutos.
A5: Cómo se aplica | B5: Las hojas «Encuesta PRE» y «Encuesta POST» tienen el texto listo para imprimir o para copiar a un formulario en línea. También pueden responderse directamente en Excel, escribiendo en las celdas amarillas.
A6: Código anónimo | B6: Cada estudiante usa el mismo código en las dos encuestas para poder emparejarlas sin identificarlo: las dos primeras letras de su primer nombre, los dos últimos dígitos de su documento y su día de nacimiento con dos cifras. Ejemplo: Camila, documento terminado en 47, nacida un día 12: CA4712.
A7: Dónde se registran las respuestas | B7: En «Respuestas PRE» y «Respuestas POST», una fila por estudiante, desde la fila 7. Hay espacio para 60 estudiantes. Las preguntas de conocimiento se registran con la letra elegida (A, B, C, D, o E si marcó «No lo sé»); las escalas, con un número de 1 a 5.
A8: Qué celdas se llenan | B8: Solo las de fondo amarillo claro. La fila gris de cada hoja de respuestas es un ejemplo y no entra en los cálculos. Las celdas blancas tienen fórmulas: no hay que escribir en ellas.
A9: Taller completo o taller rápido | B9: En la hoja «Clave», celda B3, se elige qué taller se dictó. Con «Rápido» dejan de contarse los cuatro ítems de conocimiento que el taller rápido no cubre (C8 a C11), y los puntajes se calculan sobre los ocho restantes.
A10: Cómo se califica | B10: Un punto por cada respuesta correcta en los ítems que se cuentan. «No lo sé» y las respuestas en blanco valen cero. En las hojas de respuestas, las correctas se pintan de verde.
A11: Dónde se ven los resultados | B11: En la hoja «Resultados»: participación, puntaje promedio antes y después, resultados por ítem con su gráfica, autopercepción antes y después, y valoración del taller. Todo se actualiza solo al registrar respuestas.
A12: Ganancia normalizada | B12: Es la fracción de lo que se podía mejorar que efectivamente se mejoró: (% POST − % PRE) / (100 % − % PRE). Se interpreta como baja si es menor que 0.3, media entre 0.3 y 0.7, y alta desde 0.7. Fuente: Hake, R. R. (1998). Interactive-engagement versus traditional methods. American Journal of Physics, 66(1), 64–74. https://doi.org/10.1119/1.18809
A13: Supuestos de este libro | B13: Los 12 ítems de conocimiento, sus claves y las escalas de 1 a 5 fueron escritos para este taller y no han sido validados con estudiantes: conviene revisarlos antes de la primera aplicación. Con pocos estudiantes, los porcentajes por ítem cambian mucho con una sola respuesta.
A14: Si hay más de 60 estudiantes | B14: Inserta filas dentro del bloque amarillo (no al final) y copia hacia abajo las fórmulas de las columnas blancas; así los rangos de «Resultados» se amplían solos.
A16: Leyenda de colores
B17: Celda para llenar
B18: Fila de ejemplo: no se cuenta
B19: Respuesta correcta (se pinta sola)
B20: Encabezado o rótulo

Sheet Encuesta PRE
A1: Encuesta PRE: taller práctico de pruebas de hipótesis con datos metagenómicos
A2: Esta encuesta se responde antes del taller. Es anónima, no tiene nota y toma unos 10 minutos. Sirve para mejorar el taller: responde con sinceridad y, si no sabes una respuesta, no adivines.
A4: Código | B4: Tu código anónimo: dos primeras letras de tu primer nombre + dos últimos dígitos de tu documento + tu día de nacimiento con dos cifras (ejemplo: CA4712). Usa el mismo en las dos encuestas.
A6: A. Sobre ti
A7: A1 | B7: Programa o área de estudio
A8: A2 | B8: Experiencia previa programando en Python (1 = ninguna … 5 = mucha)
A9: A3 | B9: Experiencia previa con estadística (pruebas de hipótesis) (1 = ninguna … 5 = mucha)
A10: A4 | B10: Experiencia previa con datos de microbioma o metagenómica (1 = ninguna … 5 = mucha)
A12: B. ¿Qué tan capaz te sientes de…? (1 = nada capaz, 2 = poco, 3 = algo, 4 = bastante, 5 = totalmente capaz)
A13: B1 | B13: Explicar qué afirma una hipótesis nula.
A14: B2 | B14: Explicar qué significa un valor p.
A15: B3 | B15: Comprobar los supuestos de una prueba (normalidad, igualdad de varianzas).
A16: B4 | B16: Elegir entre la t de Student, la t de Welch y Mann-Whitney.
A17: B5 | B17: Distinguir una prueba para grupos independientes de una para datos pareados.
A18: B6 | B18: Comparar la abundancia de un taxón entre dos grupos de muestras.
A19: B7 | B19: Interpretar un PERMANOVA junto con un PERMDISP.
A20: B8 | B20: Reportar el resultado de una prueba: estadístico, tamaño del efecto y valor p.
A22: C. Conocimiento del tema (elige una sola opción; si no sabes, marca E: no adivines)
A23: C1 | B23: Se compara la diversidad microbiana de plantas saludables y no saludables. ¿Qué afirma la hipótesis nula?
B24: A) Que las plantas saludables tienen mayor diversidad.
B25: B) Que el estado de la planta no importa: los dos grupos tienen la misma diversidad.
B26: C) Que la diferencia observada entre los grupos es grande.
B27: D) Que los datos siguen una distribución normal.
B28: E) No lo sé.
A29: C2 | B29: Una prueba da p = 0.03. ¿Qué significa?
B30: A) Hay 3 % de probabilidad de que la hipótesis nula sea cierta.
B31: B) Hay 97 % de probabilidad de que la diferencia sea real.
B32: C) Si la hipótesis nula fuera cierta, un resultado así de extremo o más aparecería el 3 % de las veces.
B33: D) La diferencia entre los grupos es del 3 %.
B34: E) No lo sé.
A35: C3 | B35: Una prueba da p = 0.40. ¿Cuál conclusión es correcta?
B36: A) Los dos grupos son iguales.
B37: B) La prueba se aplicó mal.
B38: C) Hay 40 % de probabilidad de que los grupos sean distintos.
B39: D) No hay evidencia suficiente para afirmar que los grupos difieren.
B40: E) No lo sé.
A41: C4 | B41: En una prueba de permutaciones se barajan muchas veces las etiquetas de grupo. ¿Para qué?
B42: A) Para ver qué diferencias produce el azar cuando el grupo no importa.
B43: B) Para aumentar el número de muestras.
B44: C) Para eliminar los valores atípicos.
...

Sheet Encuesta POST
A1: Encuesta POST: taller práctico de pruebas de hipótesis con datos metagenómicos
A2: Esta encuesta se responde después del taller. Es anónima, no tiene nota y toma unos 10 minutos. Sirve para mejorar el taller: responde con sinceridad y, si no sabes una respuesta, no adivines.
A4: Código | B4: Tu código anónimo: dos primeras letras de tu primer nombre + dos últimos dígitos de tu documento + tu día de nacimiento con dos cifras (ejemplo: CA4712). Usa el mismo en las dos encuestas.
A6: B. ¿Qué tan capaz te sientes de…? (1 = nada capaz, 2 = poco, 3 = algo, 4 = bastante, 5 = totalmente capaz)
A7: B1 | B7: Explicar qué afirma una hipótesis nula.
A8: B2 | B8: Explicar qué significa un valor p.
A9: B3 | B9: Comprobar los supuestos de una prueba (normalidad, igualdad de varianzas).
A10: B4 | B10: Elegir entre la t de Student, la t de Welch y Mann-Whitney.
A11: B5 | B11: Distinguir una prueba para grupos independientes de una para datos pareados.
A12: B6 | B12: Comparar la abundancia de un taxón entre dos grupos de muestras.
A13: B7 | B13: Interpretar un PERMANOVA junto con un PERMDISP.
A14: B8 | B14: Reportar el resultado de una prueba: estadístico, tamaño del efecto y valor p.
A16: C. Conocimiento del tema (elige una sola opción; si no sabes, marca E: no adivines)
A17: C1 | B17: Se compara la diversidad microbiana de plantas saludables y no saludables. ¿Qué afirma la hipótesis nula?
B18: A) Que las plantas saludables tienen mayor diversidad.
B19: B) Que el estado de la planta no importa: los dos grupos tienen la misma diversidad.
B20: C) Que la diferencia observada entre los grupos es grande.
B21: D) Que los datos siguen una distribución normal.
B22: E) No lo sé.
A23: C2 | B23: Una prueba da p = 0.03. ¿Qué significa?
B24: A) Hay 3 % de probabilidad de que la hipótesis nula sea cierta.
B25: B) Hay 97 % de probabilidad de que la diferencia sea real.
B26: C) Si la hipótesis nula fuera cierta, un resultado así de extremo o más aparecería el 3 % de las veces.
B27: D) La diferencia entre los grupos es del 3 %.
B28: E) No lo sé.
A29: C3 | B29: Una prueba da p = 0.40. ¿Cuál conclusión es correcta?
B30: A) Los dos grupos son iguales.
B31: B) La prueba se aplicó mal.
B32: C) Hay 40 % de probabilidad de que los grupos sean distintos.
B33: D) No hay evidencia suficiente para afirmar que los grupos difieren.
B34: E) No lo sé.
A35: C4 | B35: En una prueba de permutaciones se barajan muchas veces las etiquetas de grupo. ¿Para qué?
B36: A) Para ver qué diferencias produce el azar cuando el grupo no importa.
B37: B) Para aumentar el número de muestras.
B38: C) Para eliminar los valores atípicos.
B39: D) Para que los datos sigan una distribución normal.
B40: E) No lo sé.
A41: C5 | B41: Dos estudios observan la misma diferencia de medias entre grupos. ¿De qué más depende que el valor p sea pequeño?
B42: A) Solo de la diferencia observada.
B43: B) De cuánto varían los datos y de cuántas muestras hay.
...

Sheet Clave
A1: Clave de respuestas y qué mide cada ítem de conocimiento
A3: Taller aplicado | B3: Completo | C3: Elige «Completo» o «Rápido». Con «Rápido» no se cuentan los ítems que ese taller no cubre.
A5: Ítem | B5: Tema que evalúa | C5: Episodio (taller completo) | D5: Respuesta correcta | E5: Por qué | F5: Lo cubre el taller rápido | G5: Se cuenta
A6: C1 | B6: Hipótesis nula | C6: 2 | D6: B | E6: La hipótesis nula dice que el grupo no importa; es la que se pone a prueba. | F6: Sí | G6: =IF($B$3="Rápido",F6,"Sí") -> Sí
A7: C2 | B7: Significado del valor p | C7: 2 | D7: C | E7: El valor p se calcula suponiendo que la hipótesis nula es cierta; no es la probabilidad de la hipótesis. | F7: Sí | G7: =IF($B$3="Rápido",F7,"Sí") -> Sí
A8: C3 | B8: Un p grande no demuestra igualdad | C8: 2 | D8: D | E8: No rechazar la hipótesis nula no la demuestra: puede faltar potencia. | F8: Sí | G8: =IF($B$3="Rápido",F8,"Sí") -> Sí
A9: C4 | B9: Lógica de las permutaciones | C9: 2 | D9: A | E9: Barajar etiquetas construye la distribución del estadístico bajo la hipótesis nula. | F9: Sí | G9: =IF($B$3="Rápido",F9,"Sí") -> Sí
A10: C5 | B10: De qué depende el valor p | C10: 2 | D10: B | E10: El valor p depende de la diferencia, de la variabilidad y del tamaño de muestra (Laboratorio 1). | F10: Sí | G10: =IF($B$3="Rápido",F10,"Sí") -> Sí
A11: C6 | B11: Student frente a Welch | C11: 3 | D11: D | E11: Student supone varianzas iguales; Welch usa la varianza de cada grupo por separado. | F11: Sí | G11: =IF($B$3="Rápido",F11,"Sí") -> Sí
A12: C7 | B12: Pruebas de rangos | C12: 4 | D12: C | E12: Mann-Whitney trabaja con rangos: no supone normalidad y resiste los valores atípicos. | F12: Sí | G12: =IF($B$3="Rápido",F12,"Sí") -> Sí
A13: C8 | B13: Datos pareados | C13: 4 | D13: A | E13: Son dos medidas de las mismas unidades: datos pareados. | F13: No | G13: =IF($B$3="Rápido",F13,"Sí") -> Sí
A14: C9 | B14: Profundidad de secuenciación | C14: 1 | D14: A | E14: Cada muestra tiene un número distinto de lecturas; los conteos crudos mezclan biología y técnica. | F14: No | G14: =IF($B$3="Rápido",F14,"Sí") -> Sí
A15: C10 | B15: Datos composicionales | C15: 5 | D15: B | E15: Las proporciones suman un total fijo: si una sube, las demás bajan. | F15: No | G15: =IF($B$3="Rápido",F15,"Sí") -> Sí
A16: C11 | B16: Comparaciones múltiples | C16: 5 | D16: C | E16: El 5 % de 1 000 pruebas son unas 50 falsas alarmas: hay que corregir los valores p. | F16: No | G16: =IF($B$3="Rápido",F16,"Sí") -> Sí
A17: C12 | B17: PERMANOVA y PERMDISP | C17: 6 | D17: D | E17: El PERMANOVA también reacciona a diferencias de dispersión; por eso se acompaña de PERMDISP. | F17: Sí | G17: =IF($B$3="Rápido",F17,"Sí") -> Sí
A19: Ítems que se cuentan | G19: =COUNTIF(G6:G17,"Sí") -> 12
A21: Las claves están repartidas por igual: tres ítems con cada letra (A, B, C y D). «Lo cubre el taller rápido» indica si el tema se trabaja en la versión de una hora.

Sheet Respuestas PRE
A1: Respuestas de la encuesta PRE (antes del taller)
A2: Una fila por estudiante, desde la fila 7. Llena solo las celdas amarillas. La fila gris es un ejemplo y no se cuenta. A2–A4 y B1–B8: número de 1 a 5. C1–C12: letra elegida (E = No lo sé).
A3: Respuesta correcta | N3: =Clave!$D$6 -> B | O3: =Clave!$D$7 -> C | P3: =Clave!$D$8 -> D | Q3: =Clave!$D$9 -> A | R3: =Clave!$D$10 -> B | S3: =Clave!$D$11 -> D | T3: =Clave!$D$12 -> C | U3: =Clave!$D$13 -> A | V3: =Clave!$D$14 -> A | W3: =Clave!$D$15 -> B | X3: =Clave!$D$16 -> C | Y3: =Clave!$D$17 -> D
A4: ¿Se cuenta? | N4: =Clave!$G$6 -> Sí | O4: =Clave!$G$7 -> Sí | P4: =Clave!$G$8 -> Sí | Q4: =Clave!$G$9 -> Sí | R4: =Clave!$G$10 -> Sí | S4: =Clave!$G$11 -> Sí | T4: =Clave!$G$12 -> Sí | U4: =Clave!$G$13 -> Sí | V4: =Clave!$G$14 -> Sí | W4: =Clave!$G$15 -> Sí | X4: =Clave!$G$16 -> Sí | Y4: =Clave!$G$17 -> Sí
A5: Código | B5: A1 Programa | C5: A2 | D5: A3 | E5: A4 | F5: B1 | G5: B2 | H5: B3 | I5: B4 | J5: B5 | K5: B6 | L5: B7 | M5: B8 | N5: C1 | O5: C2 | P5: C3 | Q5: C4 | R5: C5 | S5: C6 | T5: C7 | U5: C8 | V5: C9 | W5: C10 | X5: C11 | Y5: C12 | Z5: Aciertos | AA5: % de aciertos
A6: CA4712 | B6: Maestría en Ciencias | C6: 3 | D6: 2 | E6: 1 | F6: 2 | G6: 2 | H6: 1 | I6: 1 | J6: 2 | K6: 2 | L6: 1 | M6: 2 | N6: B | O6: A | P6: A | Q6: E | R6: B | S6: E | T6: A | U6: E | V6: A | W6: A | X6: B | Y6: E | Z6: =IF($A6="","",SUMPRODUCT((N6:Y6=N$3:Y$3)*(N$4:Y$4="Sí"))) -> 3 | AA6: =IF(Z6="","",Z6/Clave!$G$19) -> 0.25
Z7: =IF($A7="","",SUMPRODUCT((N7:Y7=N$3:Y$3)*(N$4:Y$4="Sí"))) | AA7: =IF(Z7="","",Z7/Clave!$G$19)
Z8: =IF($A8="","",SUMPRODUCT((N8:Y8=N$3:Y$3)*(N$4:Y$4="Sí"))) | AA8: =IF(Z8="","",Z8/Clave!$G$19)
Z9: =IF($A9="","",SUMPRODUCT((N9:Y9=N$3:Y$3)*(N$4:Y$4="Sí"))) | AA9: =IF(Z9="","",Z9/Clave!$G$19)
Z10: =IF($A10="","",SUMPRODUCT((N10:Y10=N$3:Y$3)*(N$4:Y$4="Sí"))) | AA10: =IF(Z10="","",Z10/Clave!$G$19)
Z11: =IF($A11="","",SUMPRODUCT((N11:Y11=N$3:Y$3)*(N$4:Y$4="Sí"))) | AA11: =IF(Z11="","",Z11/Clave!$G$19)
Z12: =IF($A12="","",SUMPRODUCT((N12:Y12=N$3:Y$3)*(N$4:Y$4="Sí"))) | AA12: =IF(Z12="","",Z12/Clave!$G$19)
Z13: =IF($A13="","",SUMPRODUCT((N13:Y13=N$3:Y$3)*(N$4:Y$4="Sí"))) | AA13: =IF(Z13="","",Z13/Clave!$G$19)
Z14: =IF($A14="","",SUMPRODUCT((N14:Y14=N$3:Y$3)*(N$4:Y$4="Sí"))) | AA14: =IF(Z14="","",Z14/Clave!$G$19)
Z15: =IF($A15="","",SUMPRODUCT((N15:Y15=N$3:Y$3)*(N$4:Y$4="Sí"))) | AA15: =IF(Z15="","",Z15/Clave!$G$19)
Z16: =IF($A16="","",SUMPRODUCT((N16:Y16=N$3:Y$3)*(N$4:Y$4="Sí"))) | AA16: =IF(Z16="","",Z16/Clave!$G$19)
Z17: =IF($A17="","",SUMPRODUCT((N17:Y17=N$3:Y$3)*(N$4:Y$4="Sí"))) | AA17: =IF(Z17="","",Z17/Clave!$G$19)
Z18: =IF($A18="","",SUMPRODUCT((N18:Y18=N$3:Y$3)*(N$4:Y$4="Sí"))) | AA18: =IF(Z18="","",Z18/Clave!$G$19)
... Z66: =IF($A66="","",SUMPRODUCT((N66:Y66=N$3:Y$3)*(N$4:Y$4="Sí"))) | AA66: =IF(Z66="","",Z66/Clave!$G$19)

Sheet Respuestas POST
A1: Respuestas de la encuesta POST (después del taller)
A2: Una fila por estudiante, desde la fila 7, con el mismo código que usó en la PRE. Llena solo las celdas amarillas. La fila gris es un ejemplo y no se cuenta. B1–B8 y D1–D10: número de 1 a 5. C1–C12: letra elegida (E = No lo sé). E1–E3: texto libre.
A3: Respuesta correcta | J3: =Clave!$D$6 -> B | K3: =Clave!$D$7 -> C | L3: =Clave!$D$8 -> D | M3: =Clave!$D$9 -> A | N3: =Clave!$D$10 -> B | O3: =Clave!$D$11 -> D | P3: =Clave!$D$12 -> C | Q3: =Clave!$D$13 -> A | R3: =Clave!$D$14 -> A | S3: =Clave!$D$15 -> B | T3: =Clave!$D$16 -> C | U3: =Clave!$D$17 -> D
A4: ¿Se cuenta? | J4: =Clave!$G$6 -> Sí | K4: =Clave!$G$7 -> Sí | L4: =Clave!$G$8 -> Sí | M4: =Clave!$G$9 -> Sí | N4: =Clave!$G$10 -> Sí | O4: =Clave!$G$11 -> Sí | P4: =Clave!$G$12 -> Sí | Q4: =Clave!$G$13 -> Sí | R4: =Clave!$G$14 -> Sí | S4: =Clave!$G$15 -> Sí | T4: =Clave!$G$16 -> Sí | U4: =Clave!$G$17 -> Sí
A5: Código | B5: B1 | C5: B2 | D5: B3 | E5: B4 | F5: B5 | G5: B6 | H5: B7 | I5: B8 | J5: C1 | K5: C2 | L5: C3 | M5: C4 | N5: C5 | O5: C6 | P5: C7 | Q5: C8 | R5: C9 | S5: C10 | T5: C11 | U5: C12 | V5: D1 | W5: D2 | X5: D3 | Y5: D4 | Z5: D5 | AA5: D6 | AB5: D7 | AC5: D8 | AD5: D9 | AE5: D10 | AF5: E1 | AG5: E2 | AH5: E3 | AI5: Aciertos | AJ5: % de aciertos | AK5: Aciertos PRE (mismo código) | AL5: Cambio en aciertos
A6: CA4712 | B6: 4 | C6: 4 | D6: 4 | E6: 3 | F6: 4 | G6: 4 | H6: 3 | I6: 4 | J6: B | K6: C | L6: D | M6: A | N6: B | O6: D | P6: C | Q6: B | R6: A | S6: B | T6: B | U6: D | V6: 5 | W6: 4 | X6: 5 | Y6: 5 | Z6: 4 | AA6: 4 | AB6: 5 | AC6: 4 | AD6: 3 | AE6: 5 | AF6: Qué significa el valor p y cómo se construye barajando etiquetas. | AG6: La diferencia entre PERMANOVA y PERMDISP. | AH6: Más tiempo para los laboratorios. | AI6: =IF($A6="","",SUMPRODUCT((J6:U6=J$3:U$3)*(J$4:U$4="Sí"))) -> 10 | AJ6: =IF(AI6="","",AI6/Clave!$G$19) -> 0.83333333 | AK6: ='Respuestas PRE'!Z6 -> 3 | AL6: =IF(OR(AI6="",AK6=""),"",AI6-AK6) -> 7
AI7: =IF($A7="","",SUMPRODUCT((J7:U7=J$3:U$3)*(J$4:U$4="Sí"))) | AJ7: =IF(AI7="","",AI7/Clave!$G$19) | AK7: =IF($A7="","",IFERROR(INDEX('Respuestas PRE'!$Z$7:$Z$66,MATCH($A7,'Respuestas PRE'!$A$7:$A$66,0)),"")) | AL7: =IF(OR(AI7="",AK7=""),"",AI7-AK7)
AI8: =IF($A8="","",SUMPRODUCT((J8:U8=J$3:U$3)*(J$4:U$4="Sí"))) | AJ8: =IF(AI8="","",AI8/Clave!$G$19) | AK8: =IF($A8="","",IFERROR(INDEX('Respuestas PRE'!$Z$7:$Z$66,MATCH($A8,'Respuestas PRE'!$A$7:$A$66,0)),"")) | AL8: =IF(OR(AI8="",AK8=""),"",AI8-AK8)
AI9: =IF($A9="","",SUMPRODUCT((J9:U9=J$3:U$3)*(J$4:U$4="Sí"))) | AJ9: =IF(AI9="","",AI9/Clave!$G$19) | AK9: =IF($A9="","",IFERROR(INDEX('Respuestas PRE'!$Z$7:$Z$66,MATCH($A9,'Respuestas PRE'!$A$7:$A$66,0)),"")) | AL9: =IF(OR(AI9="",AK9=""),"",AI9-AK9)
AI10: =IF($A10="","",SUMPRODUCT((J10:U10=J$3:U$3)*(J$4:U$4="Sí"))) | AJ10: =IF(AI10="","",AI10/Clave!$G$19) | AK10: =IF($A10="","",IFERROR(INDEX('Respuestas PRE'!$Z$7:$Z$66,MATCH($A10,'Respuestas PRE'!$A$7:$A$66,0)),"")) | AL10: =IF(OR(AI10="",AK10=""),"",AI10-AK10)
AI11: =IF($A11="","",SUMPRODUCT((J11:U11=J$3:U$3)*(J$4:U$4="Sí"))) | AJ11: =IF(AI11="","",AI11/Clave!$G$19) | AK11: =IF($A11="","",IFERROR(INDEX('Respuestas PRE'!$Z$7:$Z$66,MATCH($A11,'Respuestas PRE'!$A$7:$A$66,0)),"")) | AL11: =IF(OR(AI11="",AK11=""),"",AI11-AK11)
AI12: =IF($A12="","",SUMPRODUCT((J12:U12=J$3:U$3)*(J$4:U$4="Sí"))) | AJ12: =IF(AI12="","",AI12/Clave!$G$19) | AK12: =IF($A12="","",IFERROR(INDEX('Respuestas PRE'!$Z$7:$Z$66,MATCH($A12,'Respuestas PRE'!$A$7:$A$66,0)),"")) | AL12: =IF(OR(AI12="",AK12=""),"",AI12-AK12)
AI13: =IF($A13="","",SUMPRODUCT((J13:U13=J$3:U$3)*(J$4:U$4="Sí"))) | AJ13: =IF(AI13="","",AI13/Clave!$G$19) | AK13: =IF($A13="","",IFERROR(INDEX('Respuestas PRE'!$Z$7:$Z$66,MATCH($A13,'Respuestas PRE'!$A$7:$A$66,0)),"")) | AL13: =IF(OR(AI13="",AK13=""),"",AI13-AK13)
AI14: =IF($A14="","",SUMPRODUCT((J14:U14=J$3:U$3)*(J$4:U$4="Sí"))) | AJ14: =IF(AI14="","",AI14/Clave!$G$19) | AK14: =IF($A14="","",IFERROR(INDEX('Respuestas PRE'!$Z$7:$Z$66,MATCH($A14,'Respuestas PRE'!$A$7:$A$66,0)),"")) | AL14: =IF(OR(AI14="",AK14=""),"",AI14-AK14)
AI15: =IF($A15="","",SUMPRODUCT((J15:U15=J$3:U$3)*(J$4:U$4="Sí"))) | AJ15: =IF(AI15="","",AI15/Clave!$G$19) | AK15: =IF($A15="","",IFERROR(INDEX('Respuestas PRE'!$Z$7:$Z$66,MATCH($A15,'Respuestas PRE'!$A$7:$A$66,0)),"")) | AL15: =IF(OR(AI15="",AK15=""),"",AI15-AK15)
AI16: =IF($A16="","",SUMPRODUCT((J16:U16=J$3:U$3)*(J$4:U$4="Sí"))) | AJ16: =IF(AI16="","",AI16/Clave!$G$19) | AK16: =IF($A16="","",IFERROR(INDEX('Respuestas PRE'!$Z$7:$Z$66,MATCH($A16,'Respuestas PRE'!$A$7:$A$66,0)),"")) | AL16: =IF(OR(AI16="",AK16=""),"",AI16-AK16)
AI17: =IF($A17="","",SUMPRODUCT((J17:U17=J$3:U$3)*(J$4:U$4="Sí"))) | AJ17: =IF(AI17="","",AI17/Clave!$G$19) | AK17: =IF($A17="","",IFERROR(INDEX('Respuestas PRE'!$Z$7:$Z$66,MATCH($A17,'Respuestas PRE'!$A$7:$A$66,0)),"")) | AL17: =IF(OR(AI17="",AK17=""),"",AI17-AK17)
AI18: =IF($A18="","",SUMPRODUCT((J18:U18=J$3:U$3)*(J$4:U$4="Sí"))) | AJ18: =IF(AI18="","",AI18/Clave!$G$19) | AK18: =IF($A18="","",IFERROR(INDEX('Respuestas PRE'!$Z$7:$Z$66,MATCH($A18,'Respuestas PRE'!$A$7:$A$66,0)),"")) | AL18: =IF(OR(AI18="",AK18=""),"",AI18-AK18)
... AI66: =IF($A66="","",SUMPRODUCT((J66:U66=J$3:U$3)*(J$4:U$4="Sí"))) | AJ66: =IF(AI66="","",AI66/Clave!$G$19) | AK66: =IF($A66="","",IFERROR(INDEX('Respuestas PRE'!$Z$7:$Z$66,MATCH($A66,'Respuestas PRE'!$A$7:$A$66,0)),"")) | AL66: =IF(OR(AI66="",AK66=""),"",AI66-AK66)

Sheet Resultados
A1: Resultados de la encuesta pre y post
A2: Esta hoja se calcula sola a partir de «Respuestas PRE», «Respuestas POST» y «Clave». No hay que escribir en ella.
A4: 1. Participación
A5: Estudiantes que respondieron la encuesta PRE | C5: =COUNTA('Respuestas PRE'!$A$7:$A$66) -> 0
A6: Estudiantes que respondieron la encuesta POST | C6: =COUNTA('Respuestas POST'!$A$7:$A$66) -> 0
A7: Estudiantes con las dos encuestas (mismo código) | C7: =COUNT('Respuestas POST'!$AK$7:$AK$66) -> 0
A9: 2. Conocimiento del tema: todo el grupo
A10: Ítems de conocimiento que se cuentan | C10: =Clave!$G$19 -> 12
A11: Promedio de aciertos PRE | C11: =IFERROR(AVERAGE('Respuestas PRE'!$Z$7:$Z$66),"")
A12: Promedio de aciertos POST | C12: =IFERROR(AVERAGE('Respuestas POST'!$AI$7:$AI$66),"")
A13: % de aciertos PRE | C13: =IF(OR(C11="",C10=0),"",C11/C10)
A14: % de aciertos POST | C14: =IF(OR(C12="",C10=0),"",C12/C10)
A15: Cambio (puntos porcentuales) | C15: =IF(OR(C13="",C14=""),"",(C14-C13)*100)
A16: Ganancia normalizada: (POST − PRE) / (100 % − PRE) | C16: =IF(OR(C13="",C14=""),"",IF(C13=1,"",(C14-C13)/(1-C13)))
A17: Interpretación de la ganancia (baja < 0.3 ≤ media < 0.7 ≤ alta) | C17: =IF(C16="","",IF(C16>=0.7,"Alta",IF(C16>=0.3,"Media","Baja")))
A19: 3. Conocimiento del tema: solo estudiantes con las dos encuestas
A20: Promedio del cambio en aciertos (POST − PRE) | C20: =IFERROR(AVERAGE('Respuestas POST'!$AL$7:$AL$66),"")
A21: Estudiantes que mejoraron | C21: =COUNTIF('Respuestas POST'!$AL$7:$AL$66,">0") -> 0
A22: Estudiantes que quedaron igual | C22: =COUNTIF('Respuestas POST'!$AL$7:$AL$66,0) -> 0
A23: Estudiantes que bajaron | C23: =COUNTIF('Respuestas POST'!$AL$7:$AL$66,"<0") -> 0
A25: 4. Resultados por ítem de conocimiento
A26: Ítem | B26: Tema que evalúa | C26: Respuesta correcta | D26: ¿Se cuenta? | E26: % correcto PRE | F26: % correcto POST | G26: Cambio (puntos) | H26: % «No lo sé» PRE | I26: % «No lo sé» POST
A27: =Clave!A6 -> C1 | B27: =Clave!B6 -> Hipótesis nula | C27: =Clave!D6 -> B | D27: =Clave!G6 -> Sí | E27: =IF($C$5=0,"",COUNTIF('Respuestas PRE'!$N$7:$N$66,C27)/$C$5) | F27: =IF($C$6=0,"",COUNTIF('Respuestas POST'!$J$7:$J$66,C27)/$C$6) | G27: =IF(OR(E27="",F27=""),"",(F27-E27)*100) | H27: =IF($C$5=0,"",COUNTIF('Respuestas PRE'!$N$7:$N$66,"E")/$C$5) | I27: =IF($C$6=0,"",COUNTIF('Respuestas POST'!$J$7:$J$66,"E")/$C$6)
A28: =Clave!A7 -> C2 | B28: =Clave!B7 -> Significado del valor p | C28: =Clave!D7 -> C | D28: =Clave!G7 -> Sí | E28: =IF($C$5=0,"",COUNTIF('Respuestas PRE'!$O$7:$O$66,C28)/$C$5) | F28: =IF($C$6=0,"",COUNTIF('Respuestas POST'!$K$7:$K$66,C28)/$C$6) | G28: =IF(OR(E28="",F28=""),"",(F28-E28)*100) | H28: =IF($C$5=0,"",COUNTIF('Respuestas PRE'!$O$7:$O$66,"E")/$C$5) | I28: =IF($C$6=0,"",COUNTIF('Respuestas POST'!$K$7:$K$66,"E")/$C$6)
A29: =Clave!A8 -> C3 | B29: =Clave!B8 -> Un p grande no demuestra igualdad | C29: =Clave!D8 -> D | D29: =Clave!G8 -> Sí | E29: =IF($C$5=0,"",COUNTIF('Respuestas PRE'!$P$7:$P$66,C29)/$C$5) | F29: =IF($C$6=0,"",COUNTIF('Respuestas POST'!$L$7:$L$66,C29)/$C$6) | G29: =IF(OR(E29="",F29=""),"",(F29-E29)*100) | H29: =IF($C$5=0,"",COUNTIF('Respuestas PRE'!$P$7:$P$66,"E")/$C$5) | I29: =IF($C$6=0,"",COUNTIF('Respuestas POST'!$L$7:$L$66,"E")/$C$6)
A30: =Clave!A9 -> C4 | B30: =Clave!B9 -> Lógica de las permutaciones | C30: =Clave!D9 -> A | D30: =Clave!G9 -> Sí | E30: =IF($C$5=0,"",COUNTIF('Respuestas PRE'!$Q$7:$Q$66,C30)/$C$5) | F30: =IF($C$6=0,"",COUNTIF('Respuestas POST'!$M$7:$M$66,C30)/$C$6) | G30: =IF(OR(E30="",F30=""),"",(F30-E30)*100) | H30: =IF($C$5=0,"",COUNTIF('Respuestas PRE'!$Q$7:$Q$66,"E")/$C$5) | I30: =IF($C$6=0,"",COUNTIF('Respuestas POST'!$M$7:$M$66,"E")/$C$6)
A31: =Clave!A10 -> C5 | B31: =Clave!B10 -> De qué depende el valor p | C31: =Clave!D10 -> B | D31: =Clave!G10 -> Sí | E31: =IF($C$5=0,"",COUNTIF('Respuestas PRE'!$R$7:$R$66,C31)/$C$5) | F31: =IF($C$6=0,"",COUNTIF('Respuestas POST'!$N$7:$N$66,C31)/$C$6) | G31: =IF(OR(E31="",F31=""),"",(F31-E31)*100) | H31: =IF($C$5=0,"",COUNTIF('Respuestas PRE'!$R$7:$R$66,"E")/$C$5) | I31: =IF($C$6=0,"",COUNTIF('Respuestas POST'!$N$7:$N$66,"E")/$C$6)
A32: =Clave!A11 -> C6 | B32: =Clave!B11 -> Student frente a Welch | C32: =Clave!D11 -> D | D32: =Clave!G11 -> Sí | E32: =IF($C$5=0,"",COUNTIF('Respuestas PRE'!$S$7:$S$66,C32)/$C$5) | F32: =IF($C$6=0,"",COUNTIF('Respuestas POST'!$O$7:$O$66,C32)/$C$6) | G32: =IF(OR(E32="",F32=""),"",(F32-E32)*100) | H32: =IF($C$5=0,"",COUNTIF('Respuestas PRE'!$S$7:$S$66,"E")/$C$5) | I32: =IF($C$6=0,"",COUNTIF('Respuestas POST'!$O$7:$O$66,"E")/$C$6)
A33: =Clave!A12 -> C7 | B33: =Clave!B12 -> Pruebas de rangos | C33: =Clave!D12 -> C | D33: =Clave!G12 -> Sí | E33: =IF($C$5=0,"",COUNTIF('Respuestas PRE'!$T$7:$T$66,C33)/$C$5) | F33: =IF($C$6=0,"",COUNTIF('Respuestas POST'!$P$7:$P$66,C33)/$C$6) | G33: =IF(OR(E33="",F33=""),"",(F33-E33)*100) | H33: =IF($C$5=0,"",COUNTIF('Respuestas PRE'!$T$7:$T$66,"E")/$C$5) | I33: =IF($C$6=0,"",COUNTIF('Respuestas POST'!$P$7:$P$66,"E")/$C$6)
A34: =Clave!A13 -> C8 | B34: =Clave!B13 -> Datos pareados | C34: =Clave!D13 -> A | D34: =Clave!G13 -> Sí | E34: =IF($C$5=0,"",COUNTIF('Respuestas PRE'!$U$7:$U$66,C34)/$C$5) | F34: =IF($C$6=0,"",COUNTIF('Respuestas POST'!$Q$7:$Q$66,C34)/$C$6) | G34: =IF(OR(E34="",F34=""),"",(F34-E34)*100) | H34: =IF($C$5=0,"",COUNTIF('Respuestas PRE'!$U$7:$U$66,"E")/$C$5) | I34: =IF($C$6=0,"",COUNTIF('Respuestas POST'!$Q$7:$Q$66,"E")/$C$6)
A35: =Clave!A14 -> C9 | B35: =Clave!B14 -> Profundidad de secuenciación | C35: =Clave!D14 -> A | D35: =Clave!G14 -> Sí | E35: =IF($C$5=0,"",COUNTIF('Respuestas PRE'!$V$7:$V$66,C35)/$C$5) | F35: =IF($C$6=0,"",COUNTIF('Respuestas POST'!$R$7:$R$66,C35)/$C$6) | G35: =IF(OR(E35="",F35=""),"",(F35-E35)*100) | H35: =IF($C$5=0,"",COUNTIF('Respuestas PRE'!$V$7:$V$66,"E")/$C$5) | I35: =IF($C$6=0,"",COUNTIF('Respuestas POST'!$R$7:$R$66,"E")/$C$6)
A36: =Clave!A15 -> C10 | B36: =Clave!B15 -> Datos composicionales | C36: =Clave!D15 -> B | D36: =Clave!G15 -> Sí | E36: =IF($C$5=0,"",COUNTIF('Respuestas PRE'!$W$7:$W$66,C36)/$C$5) | F36: =IF($C$6=0,"",COUNTIF('Respuestas POST'!$S$7:$S$66,C36)/$C$6) | G36: =IF(OR(E36="",F36=""),"",(F36-E36)*100) | H36: =IF($C$5=0,"",COUNTIF('Respuestas PRE'!$W$7:$W$66,"E")/$C$5) | I36: =IF($C$6=0,"",COUNTIF('Respuestas POST'!$S$7:$S$66,"E")/$C$6)
A37: =Clave!A16 -> C11 | B37: =Clave!B16 -> Comparaciones múltiples | C37: =Clave!D16 -> C | D37: =Clave!G16 -> Sí | E37: =IF($C$5=0,"",COUNTIF('Respuestas PRE'!$X$7:$X$66,C37)/$C$5) | F37: =IF($C$6=0,"",COUNTIF('Respuestas POST'!$T$7:$T$66,C37)/$C$6) | G37: =IF(OR(E37="",F37=""),"",(F37-E37)*100) | H37: =IF($C$5=0,"",COUNTIF('Respuestas PRE'!$X$7:$X$66,"E")/$C$5) | I37: =IF($C$6=0,"",COUNTIF('Respuestas POST'!$T$7:$T$66,"E")/$C$6)
A38: =Clave!A17 -> C12 | B38: =Clave!B17 -> PERMANOVA y PERMDISP | C38: =Clave!D17 -> D | D38: =Clave!G17 -> Sí | E38: =IF($C$5=0,"",COUNTIF('Respuestas PRE'!$Y$7:$Y$66,C38)/$C$5) | F38: =IF($C$6=0,"",COUNTIF('Respuestas POST'!$U$7:$U$66,C38)/$C$6) | G38: =IF(OR(E38="",F38=""),"",(F38-E38)*100) | H38: =IF($C$5=0,"",COUNTIF('Respuestas PRE'!$Y$7:$Y$66,"E")/$C$5) | I38: =IF($C$6=0,"",COUNTIF('Respuestas POST'!$U$7:$U$66,"E")/$C$6)
A40: 5. Autopercepción: ¿qué tan capaz te sientes de…? (promedio en escala de 1 a 5)
A41: Ítem | B41: Afirmación | C41: Promedio PRE | D41: Promedio POST | E41: Cambio
A42: B1 | B42: Explicar qué afirma una hipótesis nula. | C42: =IFERROR(AVERAGE('Respuestas PRE'!$F$7:$F$66),"") | D42: =IFERROR(AVERAGE('Respuestas POST'!$B$7:$B$66),"") | E42: =IF(OR(C42="",D42=""),"",D42-C42)
A43: B2 | B43: Explicar qué significa un valor p. | C43: =IFERROR(AVERAGE('Respuestas PRE'!$G$7:$G$66),"") | D43: =IFERROR(AVERAGE('Respuestas POST'!$C$7:$C$66),"") | E43: =IF(OR(C43="",D43=""),"",D43-C43)
A44: B3 | B44: Comprobar los supuestos de una prueba (normalidad, igualdad de varianzas). | C44: =IFERROR(AVERAGE('Respuestas PRE'!$H$7:$H$66),"") | D44: =IFERROR(AVERAGE('Respuestas POST'!$D$7:$D$66),"") | E44: =IF(OR(C44="",D44=""),"",D44-C44)
A45: B4 | B45: Elegir entre la t de Student, la t de Welch y Mann-Whitney. | C45: =IFERROR(AVERAGE('Respuestas PRE'!$I$7:$I$66),"") | D45: =IFERROR(AVERAGE('Respuestas POST'!$E$7:$E$66),"") | E45: =IF(OR(C45="",D45=""),"",D45-C45)
...
